Workbook

Sheet Leia-me
A1: Molho — Unit Economics e Viabilidade
A3: Como usar
A4: Edite APENAS as células azuis nas abas 'Premissas' e 'Cenários'.
A5: Células pretas são fórmulas — não sobrescreva.
A6: Células amarelas são as premissas mais sensíveis (mexa aqui primeiro).
A8: Abas
A9: Premissas | B9: Todos os custos e preços. É aqui que você mexe.
A10: Custo por Lojista | B10: Quanto custa servir UM restaurante por mês, por plano.
A11: Margem por Plano | B11: Margem bruta de cada plano. Responde: 'R$ 99 dá lucro?'
A12: Projeção 24m | B12: Receita, custo, lucro e caixa mês a mês.
A13: Cenários | B13: Pessimista / Base / Otimista — sensibilidade a churn e crescimento.
A15: Premissas-chave desta versão
A16: WhatsApp = click-to-chat → custo ZERO por mensagem (decisão de produto).
A17: Pagamento cai na conta do lojista → Molho NÃO paga taxa de PSP do pedido.
A18: Molho paga PSP apenas na cobrança da própria mensalidade (~1 transação/mês).
A19: Custos de infra são estimativas de mercado (jul/2026) — ajuste com as contas reais.

Sheet Premissas
A1: Premissas
A2: Edite apenas as células AZUIS. Amarelo = mais sensível.
A4: PREÇOS DOS PLANOS (mensal)
A5: Standard — preço/mês | B5: 99 | C5: Goomer Básico: R$ 99,90
A6: Pro — preço/mês | B6: 189 | C6: Goomer Automatizar: R$ 184,90
A7: Premium — preço/mês | B7: 299 | C7: Goomer Integrar: R$ 299,90
A8: Add-on NFC-e — preço/mês | B8: 39.9 | C8: Referência de mercado
A9: Desconto do plano anual | B9: 0.3 | C9: Mercado pratica 40-60%
A10: % de clientes no plano anual | B10: 0.3
A12: MIX DE CLIENTES (deve somar 100%)
A13: % Standard | B13: 0.5
A14: % Pro | B14: 0.35
A15: % Premium | B15: 0.15
A16: Soma (deve dar 100%) | B16: =SUM(B13:B15) -> 1
A18: CUSTO VARIÁVEL POR LOJISTA / MÊS
A19: Infra: banco, Redis, hosting (share) | B19: 8 | C19: Postgres/Redis/Vercel rateado
A20: Storage + CDN de imagens (S3/CloudFront) | B20: 3 | C20: ~80 fotos + tráfego
A21: Google Maps (geocoding + mapa) | B21: 6 | C21: COM cache agressivo por CEP
A22: WhatsApp (click-to-chat) | B22: 0 | C22: Decisão de produto: custo ZERO
A23: E-mail transacional + SMS fallback OTP | B23: 2 | C23: OTP com rate limit
A24: PSP: taxa na cobrança da mensalidade | B24: 0.03 | C24: % sobre a mensalidade do Molho
A25: Observabilidade/logs (share) | B25: 2
A27: CUSTO DE SUPORTE (o mais caro e o mais ignorado)
A28: Chamados por lojista/mês | B28: 1.5 | C28: Cai com o tempo/self-service
A29: Minutos por chamado | B29: 12
A30: Custo/hora do suporte | B30: 35 | C30: CLT + encargos, ou seu tempo
A31: → Custo de suporte por lojista/mês | B31: =B28*B29/60*B30 -> 10.5
A33: CUSTOS FIXOS DA EMPRESA / MÊS
A34: Infra base (ambiente, staging, backups) | B34: 250 | C34: Independe do nº de clientes
A35: Ferramentas (GitHub, Sentry, PostHog, etc.) | B35: 300
A36: Claude Code / IA | B36: 200
A37: Contabilidade e jurídico | B37: 600 | C37: Contrato, DPA, MEI/ME
A38: Marketing e aquisição | B38: 1000 | C38: Ads, conteúdo
A39: Domínio, marca, misc. | B39: 100
A40: → Total de custo fixo/mês | B40: =SUM(B34:B39) -> 2450
A42: AQUISIÇÃO E RETENÇÃO
A43: CAC — custo de aquisição por cliente | B43: 250 | C43: Ads + tempo de venda
A44: Churn mensal | B44: 0.04 | C44: SaaS SMB BR: 3-6%/mês
A45: Novos clientes por mês (base) | B45: 8
A46: Trial → pago (conversão) | B46: 0.35
...

Sheet Custo por Lojista
A1: Custo variável para servir UM lojista / mês
A3: Componente | B3: Standard | C3: Pro | D3: Premium | E3: Observação
A4: Infra (banco, Redis, hosting) | B4: =Premissas!$B$19 -> 8 | C4: =Premissas!$B$19*1.3 -> 10.4 | D4: =Premissas!$B$19*1.8 -> 14.4 | E4: Premium usa PDV/KDS/iFood → mais carga
A5: Storage + CDN de imagens | B5: =Premissas!$B$20 -> 3 | C5: =Premissas!$B$20 -> 3 | D5: =Premissas!$B$20*1.5 -> 4.5
A6: Google Maps | B6: =Premissas!$B$21 -> 6 | C6: =Premissas!$B$21*1.5 -> 9 | D6: =Premissas!$B$21*2 -> 12 | E6: Pro/Premium têm mapa de entregas
A7: WhatsApp (click-to-chat) | B7: =Premissas!$B$22 -> 0 | C7: =Premissas!$B$22 -> 0 | D7: =Premissas!$B$22 -> 0 | E7: Custo zero — decisão de produto
A8: E-mail + SMS OTP | B8: =Premissas!$B$23 -> 2 | C8: =Premissas!$B$23 -> 2 | D8: =Premissas!$B$23 -> 2
A9: Observabilidade | B9: =Premissas!$B$25 -> 2 | C9: =Premissas!$B$25 -> 2 | D9: =Premissas!$B$25 -> 2
A10: PSP sobre a mensalidade | B10: =Premissas!$B$5*Premissas!$B$24 -> 2.97 | C10: =Premissas!$B$6*Premissas!$B$24 -> 5.67 | D10: =Premissas!$B$7*Premissas!$B$24 -> 8.97 | E10: Só na cobrança do Molho
A11: Suporte | B11: =Premissas!$B$31 -> 10.5 | C11: =Premissas!$B$31*1.2 -> 12.6 | D11: =Premissas!$B$31*1.5 -> 15.75 | E11: Plano maior gera mais chamado
A12: CUSTO TOTAL / LOJISTA / MÊS | B12: =SUM(B4:B11) -> 34.47 | C12: =SUM(C4:C11) -> 44.67 | D12: =SUM(D4:D11) -> 59.62

Sheet Margem por Plano
A1: Margem bruta por plano
A2: Responde: 'R$ 99 dá lucro?'
B4: Standard | C4: Pro | D4: Premium
A5: Preço de tabela (mensal) | B5: =Premissas!$B$5 -> 99 | C5: =Premissas!$B$6 -> 189 | D5: =Premissas!$B$7 -> 299
A6: Preço médio (com mix anual) | B6: =B5*(1-Premissas!$B$10*Premissas!$B$9) -> 90.09 | C6: =C5*(1-Premissas!$B$10*Premissas!$B$9) -> 171.99 | D6: =D5*(1-Premissas!$B$10*Premissas!$B$9) -> 272.09
A7: Custo variável / mês | B7: ='Custo por Lojista'!B12 -> 34.47 | C7: ='Custo por Lojista'!C12 -> 44.67 | D7: ='Custo por Lojista'!D12 -> 59.62
A8: Margem bruta (R$) | B8: =B6-B7 -> 55.62 | C8: =C6-C7 -> 127.32 | D8: =D6-D7 -> 212.47
A9: Margem bruta (%) | B9: =IFERROR(B8/B6,0) -> 0.61738262 | C9: =IFERROR(C8/C6,0) -> 0.7402756 | D9: =IFERROR(D8/D6,0) -> 0.78088133
A11: CAC | B11: =Premissas!$B$43 -> 250 | C11: =Premissas!$B$43 -> 250 | D11: =Premissas!$B$43 -> 250
A12: Payback do CAC (meses) | B12: =IFERROR(B11/B8,0) -> 4.494786 | C12: =IFERROR(C11/C8,0) -> 1.9635564 | D12: =IFERROR(D11/D8,0) -> 1.1766367
A13: Tempo de vida (meses) = 1/churn | B13: =IFERROR(1/Premissas!$B$44,0) -> 25 | C13: =IFERROR(1/Premissas!$B$44,0) -> 25 | D13: =IFERROR(1/Premissas!$B$44,0) -> 25
A14: LTV (margem x vida) | B14: =B8*B13 -> 1390.5 | C14: =C8*C13 -> 3183 | D14: =D8*D13 -> 5311.75
A15: LTV / CAC | B15: =IFERROR(B14/B11,0) -> 5.562 | C15: =IFERROR(C14/C11,0) -> 12.732 | D15: =IFERROR(D14/D11,0) -> 21.247
A17: Referências de saúde de SaaS:
A18: Margem bruta > 75% · LTV/CAC > 3x · Payback do CAC < 12 meses

Sheet Projeção 24m
A1: Projeção 24 meses | N1: ARPU médio (mix) | O1: ='Margem por Plano'!B6*Premissas!B13+'Margem por Plano'!C6*Premissas!B14+'Margem por Plano'!D6*Premissas!B15 -> 146.055
N2: Custo var. médio (mix) | O2: ='Margem por Plano'!B7*Premissas!B13+'Margem por Plano'!C7*Premissas!B14+'Margem por Plano'!D7*Premissas!B15 -> 41.8125
A3: Mês | B3: Clientes (início) | C3: Novos | D3: Churn | E3: Clientes (fim) | F3: Receita (MRR) | G3: Custo variável | H3: Custo fixo | I3: CAC investido | J3: Lucro do mês | K3: Caixa acumulado
A4: 1 | B4: 0 | C4: =Premissas!$B$45 -> 8 | D4: =-B4*Premissas!$B$44 -> 0 | E4: =B4+C4+D4 -> 8 | F4: =E4*$O$1 -> 1168.44 | G4: =-E4*$O$2 -> -334.5 | H4: =-Premissas!$B$40 -> -2450 | I4: =-C4*Premissas!$B$43 -> -2000 | J4: =F4+G4+H4+I4 -> -3616.06 | K4: =J4 -> -3616.06
A5: 2 | B5: =E4 -> 8 | C5: =Premissas!$B$45 -> 8 | D5: =-B5*Premissas!$B$44 -> -0.32 | E5: =B5+C5+D5 -> 15.68 | F5: =E5*$O$1 -> 2290.1424 | G5: =-E5*$O$2 -> -655.62 | H5: =-Premissas!$B$40 -> -2450 | I5: =-C5*Premissas!$B$43 -> -2000 | J5: =F5+G5+H5+I5 -> -2815.4776 | K5: =K4+J5 -> -6431.5376
A6: 3 | B6: =E5 -> 15.68 | C6: =Premissas!$B$45 -> 8 | D6: =-B6*Premissas!$B$44 -> -0.6272 | E6: =B6+C6+D6 -> 23.0528 | F6: =E6*$O$1 -> 3366.9767 | G6: =-E6*$O$2 -> -963.8952 | H6: =-Premissas!$B$40 -> -2450 | I6: =-C6*Premissas!$B$43 -> -2000 | J6: =F6+G6+H6+I6 -> -2046.9185 | K6: =K5+J6 -> -8478.4561
A7: 4 | B7: =E6 -> 23.0528 | C7: =Premissas!$B$45 -> 8 | D7: =-B7*Premissas!$B$44 -> -0.922112 | E7: =B7+C7+D7 -> 30.130688 | F7: =E7*$O$1 -> 4400.7376 | G7: =-E7*$O$2 -> -1259.8394 | H7: =-Premissas!$B$40 -> -2450 | I7: =-C7*Premissas!$B$43 -> -2000 | J7: =F7+G7+H7+I7 -> -1309.1018 | K7: =K6+J7 -> -9787.5579
A8: 5 | B8: =E7 -> 30.130688 | C8: =Premissas!$B$45 -> 8 | D8: =-B8*Premissas!$B$44 -> -1.2052275 | E8: =B8+C8+D8 -> 36.92546 | F8: =E8*$O$1 -> 5393.1481 | G8: =-E8*$O$2 -> -1543.9458 | H8: =-Premissas!$B$40 -> -2450 | I8: =-C8*Premissas!$B$43 -> -2000 | J8: =F8+G8+H8+I8 -> -600.79769 | K8: =K7+J8 -> -10388.356
A9: 6 | B9: =E8 -> 36.92546 | C9: =Premissas!$B$45 -> 8 | D9: =-B9*Premissas!$B$44 -> -1.4770184 | E9: =B9+C9+D9 -> 43.448442 | F9: =E9*$O$1 -> 6345.8622 | G9: =-E9*$O$2 -> -1816.688 | H9: =-Premissas!$B$40 -> -2450 | I9: =-C9*Premissas!$B$43 -> -2000 | J9: =F9+G9+H9+I9 -> 79.174222 | K9: =K8+J9 -> -10309.181
A10: 7 | B10: =E9 -> 43.448442 | C10: =Premissas!$B$45 -> 8 | D10: =-B10*Premissas!$B$44 -> -1.7379377 | E10: =B10+C10+D10 -> 49.710504 | F10: =E10*$O$1 -> 7260.4677 | G10: =-E10*$O$2 -> -2078.5205 | H10: =-Premissas!$B$40 -> -2450 | I10: =-C10*Premissas!$B$43 -> -2000 | J10: =F10+G10+H10+I10 -> 731.94725 | K10: =K9+J10 -> -9577.2341
A11: 8 | B11: =E10 -> 49.710504 | C11: =Premissas!$B$45 -> 8 | D11: =-B11*Premissas!$B$44 -> -1.9884202 | E11: =B11+C11+D11 -> 55.722084 | F11: =E11*$O$1 -> 8138.489 | G11: =-E11*$O$2 -> -2329.8796 | H11: =-Premissas!$B$40 -> -2450 | I11: =-C11*Premissas!$B$43 -> -2000 | J11: =F11+G11+H11+I11 -> 1358.6094 | K11: =K10+J11 -> -8218.6247
A12: 9 | B12: =E11 -> 55.722084 | C12: =Premissas!$B$45 -> 8 | D12: =-B12*Premissas!$B$44 -> -2.2288834 | E12: =B12+C12+D12 -> 61.493201 | F12: =E12*$O$1 -> 8981.3894 | G12: =-E12*$O$2 -> -2571.1845 | H12: =-Premissas!$B$40 -> -2450 | I12: =-C12*Premissas!$B$43 -> -2000 | J12: =F12+G12+H12+I12 -> 1960.205 | K12: =K11+J12 -> -6258.4197
A13: 10 | B13: =E12 -> 61.493201 | C13: =Premissas!$B$45 -> 8 | D13: =-B13*Premissas!$B$44 -> -2.459728 | E13: =B13+C13+D13 -> 67.033473 | F13: =E13*$O$1 -> 9790.5739 | G13: =-E13*$O$2 -> -2802.8371 | H13: =-Premissas!$B$40 -> -2450 | I13: =-C13*Premissas!$B$43 -> -2000 | J13: =F13+G13+H13+I13 -> 2537.7368 | K13: =K12+J13 -> -3720.6829
A14: 11 | B14: =E13 -> 67.033473 | C14: =Premissas!$B$45 -> 8 | D14: =-B14*Premissas!$B$44 -> -2.6813389 | E14: =B14+C14+D14 -> 72.352134 | F14: =E14*$O$1 -> 10567.391 | G14: =-E14*$O$2 -> -3025.2236 | H14: =-Premissas!$B$40 -> -2450 | I14: =-C14*Premissas!$B$43 -> -2000 | J14: =F14+G14+H14+I14 -> 3092.1673 | K14: =K13+J14 -> -628.51561
A15: 12 | B15: =E14 -> 72.352134 | C15: =Premissas!$B$45 -> 8 | D15: =-B15*Premissas!$B$44 -> -2.8940854 | E15: =B15+C15+D15 -> 77.458049 | F15: =E15*$O$1 -> 11313.135 | G15: =-E15*$O$2 -> -3238.7147 | H15: =-Premissas!$B$40 -> -2450 | I15: =-C15*Premissas!$B$43 -> -2000 | J15: =F15+G15+H15+I15 -> 3624.4206 | K15: =K14+J15 -> 2995.905
A16: 13 | B16: =E15 -> 77.458049 | C16: =Premissas!$B$45 -> 8 | D16: =-B16*Premissas!$B$44 -> -3.0983219 | E16: =B16+C16+D16 -> 82.359727 | F16: =E16*$O$1 -> 12029.05 | G16: =-E16*$O$2 -> -3443.6661 | H16: =-Premissas!$B$40 -> -2450 | I16: =-C16*Premissas!$B$43 -> -2000 | J16: =F16+G16+H16+I16 -> 4135.3838 | K16: =K15+J16 -> 7131.2888
... A27: 24 | B27: =E26 -> 121.78891 | C27: =Premissas!$B$45 -> 8 | D27: =-B27*Premissas!$B$44 -> -4.8715563 | E27: =B27+C27+D27 -> 124.91735 | F27: =E27*$O$1 -> 18244.804 | G27: =-E27*$O$2 -> -5223.1067 | H27: =-Premissas!$B$40 -> -2450 | I27: =-C27*Premissas!$B$43 -> -2000 | J27: =F27+G27+H27+I27 -> 8571.6969 | K27: =K26+J27 -> 81043.274
A29: Break-even = primeiro mês com 'Lucro do mês' positivo.
A30: Clientes necessários p/ break-even: | C30: =IFERROR(Premissas!B40/($O$1-$O$2),0) -> 23.50289

Sheet Cenários
A1: Cenários de sensibilidade
A2: Altere os valores azuis na aba Premissas e compare. Abaixo, o efeito de churn e aquisição no mês 24.
A4: Cenário | B4: Novos/mês | C4: Churn mensal | D4: Clientes no mês 24 (aprox.) | E4: MRR no mês 24
A5: Pessimista | B5: 4 | C5: 0.07 | D5: =IFERROR(B5/C5*(1-(1-C5)^24),0) -> 47.130122 | E5: =D5*'Projeção 24m'!$O$1 -> 6883.59
A6: Base | B6: 8 | C6: 0.04 | D6: =IFERROR(B6/C6*(1-(1-C6)^24),0) -> 124.91735 | E6: =D6*'Projeção 24m'!$O$1 -> 18244.804
A7: Otimista | B7: 15 | C7: 0.025 | D7: =IFERROR(B7/C7*(1-(1-C7)^24),0) -> 273.21506 | E7: =D7*'Projeção 24m'!$O$1 -> 39904.426
A9: Teto de longo prazo (novos/churn): | D9: =IFERROR(B6/C6,0) -> 200
A10: Nota: com churn de 4%/mês e 8 novos/mês, a base estabiliza em ~200 lojas.
A11: Para crescer além disso: reduzir churn OU aumentar aquisição. Churn é mais barato.
